<?xml version="1.0" ?>
<!-- =================================================================================== -->
<!-- |    This document was autogenerated by xacro from complet.urdf.xacro             | -->
<!-- |    EDITING THIS FILE BY HAND IS NOT RECOMMENDED                                 | -->
<!-- =================================================================================== -->
<robot xmlns:xacro="http://www.ros.org/wiki/xacro">
  <!--<xacro:include filename="$(find ur_description)/urdf/gazebo.urdf.xacro" />-->
  <!--<xacro:include filename="$(find robot_description)/urdf/torso.transmission.xacro" />-->
  <!-- Inertia parameters -->
  <!-- This mass might be incorrect -->
  <!-- These parameters are borrowed from the urcontrol.conf file
       but are not verified for the correct permutation.
       The permutation was guessed by looking at the UR5 parameters.
       Serious use of these parameters needs further inspection. -->
  <!-- Kinematic model -->
  <!-- Properties from urcontrol.conf -->
  <!-- Arbitrary offsets for shoulder/elbow joints -->
  <!-- measured from model -->
  <!-- measured from model -->
  <!-- link lengths used in model -->
  <!-- link list -->
  <link name="base_link">
    <visual>
      <origin rpy="0 0 0" xyz="0 0 0"/>
      <geometry>
        <mesh filename="package://robot_description/meshes/visual/motoman_base.stl"/>
      </geometry>
      <material name="blue">
        <color rgba="0 0 1 1"/>
      </material>
    </visual>
    <collision>
      <origin rpy="0 0 0" xyz="0 0 0"/>
      <geometry>
        <mesh filename="package://robot_description/meshes/collision/motoman_base.stl"/>
      </geometry>
      <material name="yellow">
        <color rgba="0 1 1 1"/>
      </material>
    </collision>
    <inertial>
      <mass value="15"/>
      <origin rpy="0 0 0" xyz="0.0 0.0 0.0"/>
      <inertia ixx="1.2499995" ixy="0.0" ixz="0.0" iyy="1.2499995" iyz="0.0" izz="1.875"/>
    </inertial>
  </link>
  <link name="torso_link_b1">
    <visual>
      <origin rpy="0 0 0" xyz="0 0 0"/>
      <geometry>
        <mesh filename="package://robot_description/meshes/visual/motoman_axis_b1.stl"/>
      </geometry>
      <material name="silver">
        <color rgba="0.8 0.8 0.8 1"/>
      </material>
    </visual>
    <collision>
      <origin rpy="0 0 0" xyz="0 0 0"/>
      <geometry>
        <mesh filename="package://robot_description/meshes/collision/motoman_axis_b1.stl"/>
      </geometry>
      <material name="yellow"/>
    </collision>
    <inertial>
      <mass value="15"/>
      <origin rpy="0 0 0" xyz="0.0 0.0 0.0"/>
      <inertia ixx="1.3004994798" ixy="0.0" ixz="0.0" iyy="1.3004994798" iyz="0.0" izz="1.95075"/>
    </inertial>
  </link>
  <!--<link name="${prefix}link_b2">
			<visual>
				<origin rpy="0 0 0" xyz="0 0 0"/>
				<geometry>
					<mesh filename="package://robot_description/meshes/visual/motoman_axis_b1.stl"/>
				</geometry>
				<material name="silver">
					<color rgba="0.8 0.8 0.8 1"/>
				</material>
			</visual>
			<collision>
				<origin rpy="0 0 0" xyz="0 0 0"/>
				<geometry>
					<mesh filename="package://robot_description/meshes/collision/motoman_axis_b1.stl" />
				</geometry>
				<material name="yellow"/>
			</collision>
<xacro:cylinder_inertial radius="0.075" length="0.038" mass="25">
        <origin xyz="0.0 0.0 0.0" rpy="0 0 0" />
      </xacro:cylinder_inertial>
		</link>
-->
  <!-- joint list -->
  <joint name="torso_joint_b1" type="fixed">
    <parent link="base_link"/>
    <child link="torso_link_b1"/>
    <origin rpy="0 0 0" xyz="0.09257 0 0.8835"/>
    <axis xyz="0 0 1"/>
    <!--<limit lower="-2.9570" upper="2.9570" effort="100" velocity="2.26" />
<dynamics damping="0.0" friction="0.0"/>-->
  </joint>
  <!--<joint name="${prefix}joint_b2" type="revolute">
			<parent link="base_link"/>
			<child link="${prefix}link_b2"/>
			<origin xyz="0.09257 0 0.8835" rpy="0 0 0"/>
			<axis xyz="0 0 1" />
			<limit lower="-2.9570" upper="2.9570" effort="100" velocity="2.26" />
			<mimic joint="${prefix}joint_b1" multiplier="1" offset="0"/>
<dynamics damping="0.0" friction="0.0"/>
		</joint>
-->
  <!-- end of joint list -->
  <!-- nothing to do here at the moment -->
  <!--<xacro:torso_transmission prefix="${prefix}" />-->
   &gt;

  <!--links-->
  <link name="arm_left_base_link2">
    <visual>
      <origin rpy="0 0 0" xyz="0 0 0"/>
      <geometry>
        <mesh filename="package://robot_description/meshes/Base.dae"/>
      </geometry>
      <material name="LightGrey">
        <color rgba="0.7 0.7 0.7 1.0"/>
      </material>
    </visual>
    <collision>
      <origin rpy="0 0 0" xyz="0 0 0"/>
      <geometry>
        <mesh filename="package://robot_description/meshes/base.stl"/>
      </geometry>
    </collision>
    <inertial>
      <mass value="4.0"/>
      <origin rpy="0 0 0" xyz="0.0 0.0 0.0"/>
      <inertia ixx="0.0061063308908" ixy="0.0" ixz="0.0" iyy="0.0061063308908" iyz="0.0" izz="0.01125"/>
    </inertial>
  </link>
  <!--link2-->
  <link name="arm_left_shoulder_link">
    <visual>
      <geometry>
        <mesh filename="package://robot_description/meshes/Shoulder.dae"/>
      </geometry>
      <material name="LightGrey">
        <color rgba="0.7 0.7 0.7 1.0"/>
      </material>
    </visual>
    <collision>
      <origin rpy="0 0 0" xyz="0 0 0"/>
      <geometry>
        <mesh filename="package://robot_description/meshes/shoulder.stl"/>
      </geometry>
    </collision>
    <inertial>
      <mass value="7.778"/>
      <origin rpy="0 0 0" xyz="0.0 0.0 0.0"/>
      <inertia ixx="0.0314743125769" ixy="0.0" ixz="0.0" iyy="0.0314743125769" iyz="0.0" izz="0.021875625"/>
    </inertial>
  </link>
  <!--link3-->
  <link name="arm_left_upper_arm_link">
    <visual>
      <geometry>
        <mesh filename="package://robot_description/meshes/UpperArm.dae"/>
      </geometry>
      <material name="LightGrey">
        <color rgba="0.7 0.7 0.7 1.0"/>
      </material>
    </visual>
    <collision>
      <geometry>
        <mesh filename="package://robot_description/meshes/upper_arm.stl"/>
      </geometry>
    </collision>
    <inertial>
      <mass value="12.93"/>
      <origin rpy="0 0 0" xyz="0.0 0.0 0.306"/>
      <inertia ixx="0.421753803798" ixy="0.0" ixz="0.0" iyy="0.421753803798" iyz="0.0" izz="0.036365625"/>
    </inertial>
  </link>
  <!--link4-->
  <link name="arm_left_forearm_link">
    <visual>
      <geometry>
        <mesh filename="package://robot_description/meshes/Forearm.dae"/>
      </geometry>
      <material name="LightGrey">
        <color rgba="0.7 0.7 0.7 1.0"/>
      </material>
    </visual>
    <collision>
      <geometry>
        <mesh filename="package://robot_description/meshes/forearm.stl"/>
      </geometry>
    </collision>
    <inertial>
      <mass value="3.87"/>
      <origin rpy="0 0 0" xyz="0.0 0.0 0.28615"/>
      <inertia ixx="0.111069694097" ixy="0.0" ixz="0.0" iyy="0.111069694097" iyz="0.0" izz="0.010884375"/>
    </inertial>
  </link>
  <!--link5-->
  <link name="arm_left_wrist_1_link">
    <visual>
      <geometry>
        <mesh filename="package://robot_description/meshes/Wrist1.dae"/>
      </geometry>
      <material name="LightGrey">
        <color rgba="0.7 0.7 0.7 1.0"/>
      </material>
    </visual>
    <collision>
      <geometry>
        <mesh filename="package://robot_description/meshes/wrist_1.stl"/>
      </geometry>
    </collision>
    <inertial>
      <mass value="1.96"/>
      <origin rpy="0 0 0" xyz="0.0 0.0 0.0"/>
      <inertia ixx="0.0051082479567" ixy="0.0" ixz="0.0" iyy="0.0051082479567" iyz="0.0" izz="0.0055125"/>
    </inertial>
  </link>
  <!--link6-->
  <link name="arm_left_wrist_2_link">
    <visual>
      <geometry>
        <mesh filename="package://robot_description/meshes/Wrist2.dae"/>
      </geometry>
      <material name="LightGrey">
        <color rgba="0.7 0.7 0.7 1.0"/>
      </material>
    </visual>
    <collision>
      <geometry>
        <mesh filename="package://robot_description/meshes/wrist_2.stl"/>
      </geometry>
    </collision>
    <inertial>
      <mass value="1.96"/>
      <origin rpy="0 0 0" xyz="0.0 0.0 0.0"/>
      <inertia ixx="0.0051082479567" ixy="0.0" ixz="0.0" iyy="0.0051082479567" iyz="0.0" izz="0.0055125"/>
    </inertial>
  </link>
  <!--link7-->
  <link name="arm_left_wrist_3_link">
    <visual>
      <geometry>
        <mesh filename="package://robot_description/meshes/Wrist3.dae"/>
      </geometry>
      <material name="LightGrey">
        <color rgba="0.7 0.7 0.7 1.0"/>
      </material>
    </visual>
    <collision>
      <geometry>
        <mesh filename="package://robot_description/meshes/wrist_3.stl"/>
      </geometry>
    </collision>
    <inertial>
      <mass value="0.202"/>
      <origin rpy="0 0 0" xyz="0.0 0.0 0.0"/>
      <inertia ixx="0.000526462289415" ixy="0.0" ixz="0.0" iyy="0.000526462289415" iyz="0.0" izz="0.000568125"/>
    </inertial>
  </link>
  <!--link8-->
  <link name="arm_left_ee_link">
    <collision>
      <geometry>
        <box size="0.01 0.01 0.01"/>
      </geometry>
      <origin rpy="0 0 0" xyz="-0.01 0 0"/>
    </collision>
  </link>
  <!--joints-->
  <!---joint1-->
  <joint name="arm_left_joint_torso_fixe" type="fixed">
    <parent link="torso_link_b1"/>
    <child link="arm_left_base_link2"/>
    <origin rpy="1.57 -1.57 0.0" xyz="0.09996 -0.12 0.32214"/>
    <axis xyz="0 0 -1.0"/>
    <!--<limit lower="-2.9570" upper="2.9570" effort="100" velocity="2.26" />
    -->
    <dynamics damping="0.0" friction="0.0"/>
  </joint>
  <!--joint2-->
  <joint name="arm_left_shoulder_pan_joint" type="revolute">
    <parent link="arm_left_base_link2"/>
    <child link="arm_left_shoulder_link"/>
    <!--<origin xyz="0.0 0.0 ${shoulder_height}" rpy="0.0 0 1.57" />
      <axis xyz="0  0 1" />-->
    <origin rpy="0.0 0.0 0.0" xyz="0.0 0.0 0.1273"/>
    <axis xyz="0 0 1"/>
    <limit effort="100" lower="-2.9570" upper="2.9570" velocity="2.26"/>
    <dynamics damping="0.0" friction="0.0"/>
  </joint>
  <!--joint3-->
  <joint name="arm_left_shoulder_lift_joint" type="revolute">
    <parent link="arm_left_shoulder_link"/>
    <child link="arm_left_upper_arm_link"/>
    <origin rpy="0 0 0.0" xyz="0.0 0.220941 0.0"/>
    <axis xyz="0 1 0"/>
    <limit effort="100" lower="-2.9570" upper="2.9570" velocity="2.26"/>
    <dynamics damping="0.0" friction="0.0"/>
  </joint>
  <!--joint4-->
  <joint name="arm_left_elbow_joint" type="revolute">
    <parent link="arm_left_upper_arm_link"/>
    <child link="arm_left_forearm_link"/>
    <origin rpy="0.0 0.0 0.0" xyz="0.0 -0.1719 0.612"/>
    <axis xyz="0 1 0"/>
    <limit effort="100" lower="-2.9570" upper="2.9570" velocity="2.26"/>
    <dynamics damping="0.0" friction="0.0"/>
  </joint>
  <!--joint5-->
  <joint name="arm_left_wrist_1_joint" type="revolute">
    <parent link="arm_left_forearm_link"/>
    <child link="arm_left_wrist_1_link"/>
    <origin rpy="0.0 0.0 0.0" xyz="0.0 0.0 0.5723"/>
    <axis xyz="0 1 0"/>
    <limit effort="100" lower="-2.9570" upper="2.9570" velocity="2.26"/>
    <dynamics damping="0.0" friction="0.0"/>
  </joint>
  <!--joint6-->
  <joint name="arm_left_wrist_2_joint" type="revolute">
    <parent link="arm_left_wrist_1_link"/>
    <child link="arm_left_wrist_2_link"/>
    <origin rpy="0.0 0.0 0.0" xyz="0.0 0.1149 0.0"/>
    <axis xyz="0 0 1"/>
    <limit effort="100" lower="-2.9570" upper="2.9570" velocity="2.26"/>
    <dynamics damping="0.0" friction="0.0"/>
  </joint>
  <!--joint7-->
  <joint name="arm_left_wrist_3_joint" type="revolute">
    <parent link="arm_left_wrist_2_link"/>
    <child link="arm_left_wrist_3_link"/>
    <origin rpy="0.0 0.0 0.0" xyz="0.0 0.0 0.1157"/>
    <axis xyz="0 1 0"/>
    <limit effort="100" lower="-2.9570" upper="2.9570" velocity="2.26"/>
    <dynamics damping="0.0" friction="0.0"/>
  </joint>
  <!--joint8-->
  <joint name="arm_left_ee_fixed_joint" type="fixed">
    <parent link="arm_left_wrist_3_link"/>
    <child link="arm_left_ee_link"/>
    <origin rpy="0.0 0.0 1.570796325" xyz="0.0 0.0922 0.0"/>
  </joint>
  <transmission name="arm_left_shoulder_pan_trans">
    <type>transmission_interface/SimpleTransmission</type>
    <joint name="arm_left_shoulder_pan_joint">
      <hardwareInterface>EffortJointInterface</hardwareInterface>
    </joint>
    <actuator name="arm_left_shoulder_pan_motor">
      <mechanicalReduction>1</mechanicalReduction>
    </actuator>
  </transmission>
  <transmission name="arm_left_shoulder_lift_trans">
    <type>transmission_interface/SimpleTransmission</type>
    <joint name="arm_left_shoulder_lift_joint">
      <hardwareInterface>EffortJointInterface</hardwareInterface>
    </joint>
    <actuator name="arm_left_shoulder_lift_motor">
      <mechanicalReduction>1</mechanicalReduction>
    </actuator>
  </transmission>
  <transmission name="arm_left_elbow_trans">
    <type>transmission_interface/SimpleTransmission</type>
    <joint name="arm_left_elbow_joint">
      <hardwareInterface>EffortJointInterface</hardwareInterface>
    </joint>
    <actuator name="arm_left_elbow_motor">
      <mechanicalReduction>1</mechanicalReduction>
    </actuator>
  </transmission>
  <transmission name="arm_left_wrist_1_trans">
    <type>transmission_interface/SimpleTransmission</type>
    <joint name="arm_left_wrist_1_joint">
      <hardwareInterface>EffortJointInterface</hardwareInterface>
    </joint>
    <actuator name="arm_left_wrist_1_motor">
      <mechanicalReduction>1</mechanicalReduction>
    </actuator>
  </transmission>
  <transmission name="arm_left_wrist_2_trans">
    <type>transmission_interface/SimpleTransmission</type>
    <joint name="arm_left_wrist_2_joint">
      <hardwareInterface>EffortJointInterface</hardwareInterface>
    </joint>
    <actuator name="arm_left_wrist_2_motor">
      <mechanicalReduction>1</mechanicalReduction>
    </actuator>
  </transmission>
  <transmission name="arm_left_wrist_3_trans">
    <type>transmission_interface/SimpleTransmission</type>
    <joint name="arm_left_wrist_3_joint">
      <hardwareInterface>EffortJointInterface</hardwareInterface>
    </joint>
    <actuator name="arm_left_wrist_3_motor">
      <mechanicalReduction>1</mechanicalReduction>
    </actuator>
  </transmission>
  <!-- nothing to do here at the moment -->
   &gt;

  <!--links-->
  <link name="arm_right_base_link2">
    <visual>
      <origin rpy="0 0 0" xyz="0 0 0"/>
      <geometry>
        <mesh filename="package://robot_description/meshes/Base.dae"/>
      </geometry>
      <material name="LightGrey">
        <color rgba="0.7 0.7 0.7 1.0"/>
      </material>
    </visual>
    <collision>
      <origin rpy="0 0 0" xyz="0 0 0"/>
      <geometry>
        <mesh filename="package://robot_description/meshes/base.stl"/>
      </geometry>
    </collision>
    <inertial>
      <mass value="4.0"/>
      <origin rpy="0 0 0" xyz="0.0 0.0 0.0"/>
      <inertia ixx="0.0061063308908" ixy="0.0" ixz="0.0" iyy="0.0061063308908" iyz="0.0" izz="0.01125"/>
    </inertial>
  </link>
  <!--link2-->
  <link name="arm_right_shoulder_link">
    <visual>
      <geometry>
        <mesh filename="package://robot_description/meshes/Shoulder.dae"/>
      </geometry>
      <material name="LightGrey">
        <color rgba="0.7 0.7 0.7 1.0"/>
      </material>
    </visual>
    <collision>
      <origin rpy="0 0 0" xyz="0 0 0"/>
      <geometry>
        <mesh filename="package://robot_description/meshes/shoulder.stl"/>
      </geometry>
    </collision>
    <inertial>
      <mass value="7.778"/>
      <origin rpy="0 0 0" xyz="0.0 0.0 0.0"/>
      <inertia ixx="0.0314743125769" ixy="0.0" ixz="0.0" iyy="0.0314743125769" iyz="0.0" izz="0.021875625"/>
    </inertial>
  </link>
  <!--link3-->
  <link name="arm_right_upper_arm_link">
    <visual>
      <geometry>
        <mesh filename="package://robot_description/meshes/UpperArm.dae"/>
      </geometry>
      <material name="LightGrey">
        <color rgba="0.7 0.7 0.7 1.0"/>
      </material>
    </visual>
    <collision>
      <geometry>
        <mesh filename="package://robot_description/meshes/upper_arm.stl"/>
      </geometry>
    </collision>
    <inertial>
      <mass value="12.93"/>
      <origin rpy="0 0 0" xyz="0.0 0.0 0.306"/>
      <inertia ixx="0.421753803798" ixy="0.0" ixz="0.0" iyy="0.421753803798" iyz="0.0" izz="0.036365625"/>
    </inertial>
  </link>
  <!--link4-->
  <link name="arm_right_forearm_link">
    <visual>
      <geometry>
        <mesh filename="package://robot_description/meshes/Forearm.dae"/>
      </geometry>
      <material name="LightGrey">
        <color rgba="0.7 0.7 0.7 1.0"/>
      </material>
    </visual>
    <collision>
      <geometry>
        <mesh filename="package://robot_description/meshes/forearm.stl"/>
      </geometry>
    </collision>
    <inertial>
      <mass value="3.87"/>
      <origin rpy="0 0 0" xyz="0.0 0.0 0.28615"/>
      <inertia ixx="0.111069694097" ixy="0.0" ixz="0.0" iyy="0.111069694097" iyz="0.0" izz="0.010884375"/>
    </inertial>
  </link>
  <!--link5-->
  <link name="arm_right_wrist_1_link">
    <visual>
      <geometry>
        <mesh filename="package://robot_description/meshes/Wrist1.dae"/>
      </geometry>
      <material name="LightGrey">
        <color rgba="0.7 0.7 0.7 1.0"/>
      </material>
    </visual>
    <collision>
      <geometry>
        <mesh filename="package://robot_description/meshes/wrist_1.stl"/>
      </geometry>
    </collision>
    <inertial>
      <mass value="1.96"/>
      <origin rpy="0 0 0" xyz="0.0 0.0 0.0"/>
      <inertia ixx="0.0051082479567" ixy="0.0" ixz="0.0" iyy="0.0051082479567" iyz="0.0" izz="0.0055125"/>
    </inertial>
  </link>
  <!--link6-->
  <link name="arm_right_wrist_2_link">
    <visual>
      <geometry>
        <mesh filename="package://robot_description/meshes/Wrist2.dae"/>
      </geometry>
      <material name="LightGrey">
        <color rgba="0.7 0.7 0.7 1.0"/>
      </material>
    </visual>
    <collision>
      <geometry>
        <mesh filename="package://robot_description/meshes/wrist_2.stl"/>
      </geometry>
    </collision>
    <inertial>
      <mass value="1.96"/>
      <origin rpy="0 0 0" xyz="0.0 0.0 0.0"/>
      <inertia ixx="0.0051082479567" ixy="0.0" ixz="0.0" iyy="0.0051082479567" iyz="0.0" izz="0.0055125"/>
    </inertial>
  </link>
  <!--link7-->
  <link name="arm_right_wrist_3_link">
    <visual>
      <geometry>
        <mesh filename="package://robot_description/meshes/Wrist3.dae"/>
      </geometry>
      <material name="LightGrey">
        <color rgba="0.7 0.7 0.7 1.0"/>
      </material>
    </visual>
    <collision>
      <geometry>
        <mesh filename="package://robot_description/meshes/wrist_3.stl"/>
      </geometry>
    </collision>
    <inertial>
      <mass value="0.202"/>
      <origin rpy="0 0 0" xyz="0.0 0.0 0.0"/>
      <inertia ixx="0.000526462289415" ixy="0.0" ixz="0.0" iyy="0.000526462289415" iyz="0.0" izz="0.000568125"/>
    </inertial>
  </link>
  <!--link8-->
  <link name="arm_right_ee_link">
    <collision>
      <geometry>
        <box size="0.01 0.01 0.01"/>
      </geometry>
      <origin rpy="0 0 0" xyz="-0.01 0 0"/>
    </collision>
  </link>
  <!--joints-->
  <!---joint1-->
  <joint name="arm_right_joint_torso_fixe" type="fixed">
    <parent link="torso_link_b1"/>
    <child link="arm_right_base_link2"/>
    <origin rpy="1.57 -1.57 -3.14" xyz="0.09996 0.12 0.32214"/>
    <axis xyz="0 0 1.0"/>
    <!--<limit lower="-2.9570" upper="2.9570" effort="100" velocity="2.26" />
    -->
    <dynamics damping="0.0" friction="0.0"/>
  </joint>
  <!--joint2-->
  <joint name="arm_right_shoulder_pan_joint" type="revolute">
    <parent link="arm_right_base_link2"/>
    <child link="arm_right_shoulder_link"/>
    <!--<origin xyz="0.0 0.0 ${shoulder_height}" rpy="0.0 0 1.57" />
      <axis xyz="0  0 1" />-->
    <origin rpy="0.0 0.0 0.0" xyz="0.0 0.0 0.1273"/>
    <axis xyz="0 0 1"/>
    <limit effort="100" lower="-2.9570" upper="2.9570" velocity="2.26"/>
    <dynamics damping="0.0" friction="0.0"/>
  </joint>
  <!--joint3-->
  <joint name="arm_right_shoulder_lift_joint" type="revolute">
    <parent link="arm_right_shoulder_link"/>
    <child link="arm_right_upper_arm_link"/>
    <origin rpy="0 0 0.0" xyz="0.0 0.220941 0.0"/>
    <axis xyz="0 1 0"/>
    <limit effort="100" lower="-2.9570" upper="2.9570" velocity="2.26"/>
    <dynamics damping="0.0" friction="0.0"/>
  </joint>
  <!--joint4-->
  <joint name="arm_right_elbow_joint" type="revolute">
    <parent link="arm_right_upper_arm_link"/>
    <child link="arm_right_forearm_link"/>
    <origin rpy="0.0 0.0 0.0" xyz="0.0 -0.1719 0.612"/>
    <axis xyz="0 1 0"/>
    <limit effort="100" lower="-2.9570" upper="2.9570" velocity="2.26"/>
    <dynamics damping="0.0" friction="0.0"/>
  </joint>
  <!--joint5-->
  <joint name="arm_right_wrist_1_joint" type="revolute">
    <parent link="arm_right_forearm_link"/>
    <child link="arm_right_wrist_1_link"/>
    <origin rpy="0.0 0.0 0.0" xyz="0.0 0.0 0.5723"/>
    <axis xyz="0 1 0"/>
    <limit effort="100" lower="-2.9570" upper="2.9570" velocity="2.26"/>
    <dynamics damping="0.0" friction="0.0"/>
  </joint>
  <!--joint6-->
  <joint name="arm_right_wrist_2_joint" type="revolute">
    <parent link="arm_right_wrist_1_link"/>
    <child link="arm_right_wrist_2_link"/>
    <origin rpy="0.0 0.0 0.0" xyz="0.0 0.1149 0.0"/>
    <axis xyz="0 0 1"/>
    <limit effort="100" lower="-2.9570" upper="2.9570" velocity="2.26"/>
    <dynamics damping="0.0" friction="0.0"/>
  </joint>
  <!--joint7-->
  <joint name="arm_right_wrist_3_joint" type="revolute">
    <parent link="arm_right_wrist_2_link"/>
    <child link="arm_right_wrist_3_link"/>
    <origin rpy="0.0 0.0 0.0" xyz="0.0 0.0 0.1157"/>
    <axis xyz="0 1 0"/>
    <limit effort="100" lower="-2.9570" upper="2.9570" velocity="2.26"/>
    <dynamics damping="0.0" friction="0.0"/>
  </joint>
  <!--joint8-->
  <joint name="arm_right_ee_fixed_joint" type="fixed">
    <parent link="arm_right_wrist_3_link"/>
    <child link="arm_right_ee_link"/>
    <origin rpy="0.0 0.0 1.570796325" xyz="0.0 0.0922 0.0"/>
  </joint>
  <transmission name="arm_right_shoulder_pan_trans">
    <type>transmission_interface/SimpleTransmission</type>
    <joint name="arm_right_shoulder_pan_joint">
      <hardwareInterface>EffortJointInterface</hardwareInterface>
    </joint>
    <actuator name="arm_right_shoulder_pan_motor">
      <mechanicalReduction>1</mechanicalReduction>
    </actuator>
  </transmission>
  <transmission name="arm_right_shoulder_lift_trans">
    <type>transmission_interface/SimpleTransmission</type>
    <joint name="arm_right_shoulder_lift_joint">
      <hardwareInterface>EffortJointInterface</hardwareInterface>
    </joint>
    <actuator name="arm_right_shoulder_lift_motor">
      <mechanicalReduction>1</mechanicalReduction>
    </actuator>
  </transmission>
  <transmission name="arm_right_elbow_trans">
    <type>transmission_interface/SimpleTransmission</type>
    <joint name="arm_right_elbow_joint">
      <hardwareInterface>EffortJointInterface</hardwareInterface>
    </joint>
    <actuator name="arm_right_elbow_motor">
      <mechanicalReduction>1</mechanicalReduction>
    </actuator>
  </transmission>
  <transmission name="arm_right_wrist_1_trans">
    <type>transmission_interface/SimpleTransmission</type>
    <joint name="arm_right_wrist_1_joint">
      <hardwareInterface>EffortJointInterface</hardwareInterface>
    </joint>
    <actuator name="arm_right_wrist_1_motor">
      <mechanicalReduction>1</mechanicalReduction>
    </actuator>
  </transmission>
  <transmission name="arm_right_wrist_2_trans">
    <type>transmission_interface/SimpleTransmission</type>
    <joint name="arm_right_wrist_2_joint">
      <hardwareInterface>EffortJointInterface</hardwareInterface>
    </joint>
    <actuator name="arm_right_wrist_2_motor">
      <mechanicalReduction>1</mechanicalReduction>
    </actuator>
  </transmission>
  <transmission name="arm_right_wrist_3_trans">
    <type>transmission_interface/SimpleTransmission</type>
    <joint name="arm_right_wrist_3_joint">
      <hardwareInterface>EffortJointInterface</hardwareInterface>
    </joint>
    <actuator name="arm_right_wrist_3_motor">
      <mechanicalReduction>1</mechanicalReduction>
    </actuator>
  </transmission>
  <!-- nothing to do here at the moment -->
</robot>

