<?xml version="1.0" ?>
<robot  xmlns:xacro="http://ros.org/wiki/xacro">

<!--<xacro:include filename="$(find robot_description)/urdf/ur10.gazebo.xacro" />-->
<xacro:include filename="$(find robot_description)/urdf/torso.transmission.xacro" />



<xacro:macro name="cylinder_inertial" params="radius length mass *origin">
    <inertial>
      <mass value="${mass}" />
      <insert_block name="origin" />
      <inertia ixx="${0.0833333 * mass * (3 * radius * radius + length * length)}" ixy="0.0" ixz="0.0"
        iyy="${0.0833333 * mass * (3 * radius * radius + length * length)}" iyz="0.0"
        izz="${0.5 * mass * radius * radius}" />
    </inertial>
  </xacro:macro>


	<xacro:macro name="torso" params="name prefix">



		<!-- link list -->
		<link name="base_link">
			<visual>
<origin rpy="0 0 0" xyz="0 0 0"/>
				<geometry>
					<mesh filename="package://robot_description/meshes/visual/motoman_base.stl" />
				</geometry>
				<material name="blue">
					<color rgba="0 0 1 1"/>
				</material>
			</visual>
			<collision>
<origin rpy="0 0 0" xyz="0 0 0"/>
				<geometry>
					<mesh filename="package://robot_description/meshes/collision/motoman_base.stl" />
				</geometry>
				<material name="yellow">
					<color rgba="0 1 1 1"/>
				</material>
			</collision>
<xacro:cylinder_inertial radius="0.5" length="0.5" mass="15">
        <origin xyz="0.0 0.0 0.0" rpy="0 0 0" />
      </xacro:cylinder_inertial>
		</link>
		<link name="${prefix}link_b1">
			<visual>
				<origin rpy="0 0 0" xyz="0 0 0"/>
				<geometry>
					<mesh filename="package://robot_description/meshes/visual/motoman_axis_b1.stl"/>
				</geometry>
				<material name="silver">
					<color rgba="0.8 0.8 0.8 1"/>
				</material>
			</visual>
			<collision>
				<origin rpy="0 0 0" xyz="0 0 0"/>
				<geometry>
					<mesh filename="package://robot_description/meshes/collision/motoman_axis_b1.stl" />
				</geometry>
				<material name="yellow"/>
			</collision>
<xacro:cylinder_inertial radius="0.51" length="0.51" mass="15">
        <origin xyz="0.0 0.0 0.0" rpy="0 0 0" />
      </xacro:cylinder_inertial>
		</link>
		<!--<link name="${prefix}link_b2">
			<visual>
				<origin rpy="0 0 0" xyz="0 0 0"/>
				<geometry>
					<mesh filename="package://robot_description/meshes/visual/motoman_axis_b1.stl"/>
				</geometry>
				<material name="silver">
					<color rgba="0.8 0.8 0.8 1"/>
				</material>
			</visual>
			<collision>
				<origin rpy="0 0 0" xyz="0 0 0"/>
				<geometry>
					<mesh filename="package://robot_description/meshes/collision/motoman_axis_b1.stl" />
				</geometry>
				<material name="yellow"/>
			</collision>
<xacro:cylinder_inertial radius="0.075" length="0.038" mass="25">
        <origin xyz="0.0 0.0 0.0" rpy="0 0 0" />
      </xacro:cylinder_inertial>
		</link>
-->

		<!-- joint list -->
		<joint name="${prefix}joint_b1" type="revolute">
			<parent link="base_link"/>
			<child link="${prefix}link_b1"/>
			<origin xyz="0.09257 0 0.8835" rpy="0 0 0"/>
			<axis xyz="0 0 1" />
			<limit lower="-2.9570" upper="2.9570" effort="300" velocity="2.26" />
<dynamics damping="0.0" friction="0.0"/>
		</joint>
		<!--<joint name="${prefix}joint_b2" type="revolute">
			<parent link="base_link"/>
			<child link="${prefix}link_b2"/>
			<origin xyz="0.09257 0 0.8835" rpy="0 0 0"/>
			<axis xyz="0 0 1" />
			<limit lower="-2.9570" upper="2.9570" effort="100" velocity="2.26" />
			<mimic joint="${prefix}joint_b1" multiplier="1" offset="0"/>
<dynamics damping="0.0" friction="0.0"/>
		</joint>
-->
		<!-- end of joint list -->


 

  <!--  <xacro:ur10_arm_gazebo prefix="${prefix}" />-->
  <xacro:torso_transmission prefix="${prefix}" />
	</xacro:macro>
</robot>
